<?xml version="1.0"?>
<robot name="crazyflie">

    <material name="white">
        <color rgba="1 1 1 1.0" />
    </material>
    
    <link name="base_footprint">
    </link>
    <joint name="base_link_joint" type="fixed">
        <parent link="base_footprint" />
        <child link="base_link" />
    </joint>

    <link name="base_link">
        <visual name="body_visual">
            <geometry>
                <mesh filename="package://crazyflie_lcis_description/models/crazyflie/meshes/collada_files/cf2_assembly.dae" scale="1.00 1.00 1.00"/>                
            </geometry>
            <origin xyz="0 0 17.425E-3" rpy="0 0 0"/>
            <!-- <material name="white" /> -->

        </visual>

        <inertial>
            <origin xyz="0 0 17.425E-3" rpy="0 0 0"/>
            <mass value="0.025"/>
            <inertia 
                ixx="1.6572e-05" ixy="0.0"    ixz="0.0"
                iyy="1.6656e-05" iyz="0.0"
                izz="2.9262e-05"/>
        </inertial>

        <collision name="body_collision">
            <origin xyz="0 0 17.425E-3" rpy="0 0 0"/>
            <geometry>
                <box size="0.10 0.10 0.03"/>
            </geometry>
        </collision>
    </link>

    <link name="m1_prop">
        <visual name="m1_visual">
            <geometry>
                <mesh filename="package://crazyflie_lcis_description/models/crazyflie/meshes/collada_files/ccw_prop.dae" scale="1.00 1.00 1.00" />
            </geometry>
            <origin xyz="0 0 0" rpy="0 0 0"/>
        </visual>

        <inertial>
            <origin xyz="0 0 0" rpy="0 0 0"/>
            <mass value="0.0008"/>
            <inertia 
                ixx="1.6667e-07" ixy="0.0"    ixz="0.0"
                iyy="5.8333e-08" iyz="0.0"
                izz="1.176e-07"/>
        </inertial>
    </link>

    <link name="m2_prop">
        <visual name="m2_visual">
            <geometry>
                <mesh filename="package://crazyflie_lcis_description/models/crazyflie/meshes/collada_files/cw_prop.dae" scale="1.00 1.00 1.00" />
            </geometry>
            <origin xyz="0 0 0" rpy="0 0 0"/>
        </visual>

        <inertial>
            <origin xyz="0 0 0" rpy="0 0 0"/>
            <mass value="0.0008"/>
            <inertia 
                ixx="1.6667e-07" ixy="0.0"    ixz="0.0"
                iyy="5.8333e-08" iyz="0.0"
                izz="1.176e-07"/>
        </inertial>
    </link>

    <link name="m3_prop">
        <visual name="m3_visual">
            <geometry>
                <mesh filename="package://crazyflie_lcis_description/models/crazyflie/meshes/collada_files/ccw_prop.dae" scale="1.00 1.00 1.00" />
            </geometry>
            <origin xyz="0 0 0" rpy="0 0 0"/>
        </visual>

        <inertial>
            <origin xyz="0 0 0" rpy="0 0 0"/>
            <mass value="0.0008"/>
            <inertia 
                ixx="1.6667e-07" ixy="0.0"    ixz="0.0"
                iyy="5.8333e-08" iyz="0.0"
                izz="1.176e-07"/>
        </inertial>
    </link>

    <link name="m4_prop">
        <visual name="m4_visual">
            <geometry>
                <mesh filename="package://crazyflie_lcis_description/models/crazyflie/meshes/collada_files/cw_prop.dae" scale="1.00 1.00 1.00" />
            </geometry>
            <origin xyz="0 0 0" rpy="0 0 0"/>
        </visual>

        <inertial>
            <origin xyz="0 0 0" rpy="0 0 0"/>
            <mass value="0.0008"/>
            <inertia 
                ixx="1.6667e-07" ixy="0.0"    ixz="0.0"
                iyy="5.8333e-08" iyz="0.0"
                izz="1.176e-07"/>
        </inertial>
    </link>

    <joint name="m1_joint" type="revolute">
        <parent link="base_link" />
        <child link="m1_prop" />
        <origin xyz="0.031 -0.031 0.021" rpy="0 0 0"/>
        <axis xyz="0 0 1"/>
        <limit lower="-1e+16" upper="1e+16" effort="10" velocity="1000"/>
    </joint>

    <joint name="m2_joint" type="revolute">
        <parent link="base_link" />
        <child link="m2_prop" />
        <origin xyz="-0.031 -0.031 0.021" rpy="0 0 0"/>
        <axis xyz="0 0 1"/>
        <limit lower="-1e+16" upper="1e+16" effort="10" velocity="1000"/>
    </joint>

    <joint name="m3_joint" type="revolute">
        <parent link="base_link" />
        <child link="m3_prop" />
        <origin xyz="-0.031 0.031 0.021" rpy="0 0 0"/>
        <axis xyz="0 0 1"/>
        <limit lower="-1e+16" upper="1e+16" effort="10" velocity="1000"/>
    </joint>

    <joint name="m4_joint" type="revolute">
        <parent link="base_link" />
        <child link="m4_prop" />
        <origin xyz="0.031 0.031 0.021" rpy="0 0 0"/>
        <axis xyz="0 0 1"/>
        <limit lower="-1e+16" upper="1e+16" effort="10" velocity="1000"/>
    </joint>

    <gazebo>
        <plugin
            filename="gz-sim-multicopter-motor-model-system"
            name="gz::sim::systems::MulticopterMotorModel">
            <robotNamespace>crazyflie</robotNamespace>
            <jointName>m1_joint</jointName>
            <linkName>m1_prop</linkName>
            <turningDirection>ccw</turningDirection>
            <timeConstantUp>0.0125</timeConstantUp>
            <timeConstantDown>0.025</timeConstantDown>
            <maxRotVelocity>3052</maxRotVelocity>
            <motorConstant>1.7965e-8</motorConstant>
            <momentConstant>0.005964552</momentConstant>
            <commandSubTopic>command/motor_speed</commandSubTopic>
            <actuator_number>0</actuator_number>
            <rotorDragCoefficient>9.1785e-7</rotorDragCoefficient>
            <rollingMomentCoefficient>0.0000001</rollingMomentCoefficient>
            <motorSpeedPubTopic>motor_speed/0</motorSpeedPubTopic>
            <rotorVelocitySlowdownSim>70</rotorVelocitySlowdownSim>
            <motorType>velocity</motorType>
        </plugin>

        <plugin
            filename="gz-sim-multicopter-motor-model-system"
            name="gz::sim::systems::MulticopterMotorModel">
            <robotNamespace>crazyflie</robotNamespace>
            <jointName>m2_joint</jointName>
            <linkName>m2_prop</linkName>
            <turningDirection>cw</turningDirection>
            <timeConstantUp>0.0125</timeConstantUp>
            <timeConstantDown>0.025</timeConstantDown>
            <maxRotVelocity>3052</maxRotVelocity>
            <motorConstant>1.7965e-8</motorConstant>
            <momentConstant>0.005964552</momentConstant>
            <commandSubTopic>command/motor_speed</commandSubTopic>
            <actuator_number>1</actuator_number>
            <rotorDragCoefficient>9.1785e-7</rotorDragCoefficient>
            <rollingMomentCoefficient>0.0000001</rollingMomentCoefficient>
            <motorSpeedPubTopic>motor_speed/1</motorSpeedPubTopic>
            <rotorVelocitySlowdownSim>70</rotorVelocitySlowdownSim>
            <motorType>velocity</motorType>
        </plugin>

        <plugin
            filename="gz-sim-multicopter-motor-model-system"
            name="gz::sim::systems::MulticopterMotorModel">
            <robotNamespace>crazyflie</robotNamespace>
            <jointName>m3_joint</jointName>
            <linkName>m3_prop</linkName>
            <turningDirection>ccw</turningDirection>
            <timeConstantUp>0.0125</timeConstantUp>
            <timeConstantDown>0.025</timeConstantDown>
            <maxRotVelocity>3052</maxRotVelocity>
            <motorConstant>1.7965e-8</motorConstant>
            <momentConstant>0.005964552</momentConstant>
            <commandSubTopic>command/motor_speed</commandSubTopic>
            <actuator_number>2</actuator_number>
            <rotorDragCoefficient>9.1785e-7</rotorDragCoefficient>
            <rollingMomentCoefficient>0.0000001</rollingMomentCoefficient>
            <motorSpeedPubTopic>motor_speed/2</motorSpeedPubTopic>
            <rotorVelocitySlowdownSim>70</rotorVelocitySlowdownSim>
            <motorType>velocity</motorType>
        </plugin>

        <plugin
            filename="gz-sim-multicopter-motor-model-system"
            name="gz::sim::systems::MulticopterMotorModel">
            <robotNamespace>crazyflie</robotNamespace>
            <jointName>m4_joint</jointName>
            <linkName>m4_prop</linkName>
            <turningDirection>cw</turningDirection>
            <timeConstantUp>0.0125</timeConstantUp>
            <timeConstantDown>0.025</timeConstantDown>
            <maxRotVelocity>3052</maxRotVelocity>
            <motorConstant>1.7965e-8</motorConstant>
            <momentConstant>0.005964552</momentConstant>
            <commandSubTopic>command/motor_speed</commandSubTopic>
            <actuator_number>3</actuator_number>
            <rotorDragCoefficient>9.1785e-7</rotorDragCoefficient>
            <rollingMomentCoefficient>0.0000001</rollingMomentCoefficient>
            <motorSpeedPubTopic>motor_speed/3</motorSpeedPubTopic>
            <rotorVelocitySlowdownSim>70</rotorVelocitySlowdownSim>
            <motorType>velocity</motorType>
        </plugin>

        <plugin
            filename="gz-sim-odometry-publisher-system"
            name="gz::sim::systems::OdometryPublisher">
            <dimensions>3</dimensions>
            <odom_publish_frequency>200</odom_publish_frequency>
            <odom_topic>/crazyflie/odom</odom_topic>
        </plugin>

        <plugin filename="gz-sim-linearbatteryplugin-system" name="gz::sim::systems::LinearBatteryPlugin">
            <battery_name>linear_battery</battery_name>
            <voltage>3.7</voltage>
            <open_circuit_voltage_constant_coef>3.7</open_circuit_voltage_constant_coef>
            <open_circuit_voltage_linear_coef>0</open_circuit_voltage_linear_coef>
            <initial_charge>0.250</initial_charge>
            <capacity>0.250</capacity>
            <resistance>0.09</resistance>
            <power_load>4.23</power_load>
            <enable_recharge>true</enable_recharge>
            <recharge_by_topic>true</recharge_by_topic>
            <charging_time>0.17</charging_time>
            <start_on_motion>true</start_on_motion>
            <fix_issue_225>true</fix_issue_225>
        </plugin>

        <plugin
            filename="gz_crazysim_plugin"
            name="crazyflie_interface::GzCrazyflieInterface">
            <imuSubTopic>/imu</imuSubTopic>
            <magSubTopic>/mag</magSubTopic>
            <baroSubTopic>/baro</baroSubTopic>
            <cffirm_addr>INADDR_ANY</cffirm_addr>
            <cffirm_port>19950</cffirm_port>
            <cflib_addr>INADDR_ANY</cflib_addr>
            <cflib_port>19850</cflib_port>
            <cfPrefix>cf</cfPrefix>
            <cfId>0</cfId>
        </plugin>
    </gazebo>
</robot>