<?xml version="1.0" ?>
<sdf version="1.9">
    <model name="crazyflie">

        <!-- links and joints definitions-->
        <link name="crazyflie/body">
            <!-- this body link corresponds to base_link for mobile robot-->
            <pose> 0 0 17.425E-3 0 0 0</pose>

            <visual name="crazyflie/body_visual">
                <!-- normally, there is no need for name of a visual-->
                <geometry>
                    <mesh>
                        <uri>model://crazyflie_lcis_description/models/crazyflie/meshes/collada_files/cf2_assembly.dae</uri>
                    </mesh>
                </geometry>
            </visual>

            <inertial>
                <mass>0.025</mass>
                <inertia>
                    <ixx>16.571710E-06</ixx>
                    <iyy>16.655602E-06</iyy>
                    <izz>29.261652E-06</izz>
                    <ixy>0.830806E-06</ixy>
                    <ixz>0.718277E-06</ixz>
                    <iyz>1.800197E-06</iyz>
                </inertia>
            </inertial>

            <collision name="crazyflie/body_collision">
                <!-- normally, there is no need for name of a collision-->
                <geometry>
                    <box>
                        <size>0.10 0.10 0.03</size>
                    </box>
                </geometry>
            </collision>
        </link>

        <!-- Propeller 1-->
        <link name="crazyflie/m1_prop">
            <pose>0.031 -0.031 0.021 0 0 0</pose>

            <visual name="crazyflie/m1_visual">
                <geometry>
                <mesh>
                    <uri>model://crazyflie_lcis_description/models/crazyflie/meshes/collada_files/ccw_prop.dae</uri>
                </mesh>
                </geometry>
            </visual>

            <inertial>
                <mass>0.0008</mass>
                <inertia>
                <ixx>8.33333E-09</ixx>
                <iyy>1.08333E-07</iyy>
                <izz>1.13333E-07</izz>
                </inertia>
            </inertial>
        </link>

        <!-- Propeller 2-->
        <link name="crazyflie/m2_prop">
            <pose>-0.031 -0.031 0.021 0 0 0</pose>
            <visual name="crazyflie/m2_visual">
                <geometry>
                <mesh>
                    <uri>model://crazyflie_lcis_description/models/crazyflie/meshes/collada_files/cw_prop.dae</uri>
                </mesh>
                </geometry>
            </visual>

            <inertial>
                <mass>0.0008</mass>
                <inertia>
                <ixx>8.33333E-09</ixx>
                <iyy>1.08333E-07</iyy>
                <izz>1.13333E-07</izz>
                </inertia>
            </inertial>
        </link>

        <!-- Propeller 3-->
        <link name="crazyflie/m3_prop">
            <pose>-0.031 0.031 0.021 0 0 0</pose>

            <visual name="crazyflie/m3_visual">
                <geometry>
                <mesh>
                    <uri>model://crazyflie_lcis_description/models/crazyflie/meshes/collada_files/ccw_prop.dae</uri>
                </mesh>
                </geometry>
            </visual>

            <inertial>
                <mass>0.0008</mass>
                <inertia>
                <ixx>8.33333E-09</ixx>
                <iyy>1.08333E-07</iyy>
                <izz>1.13333E-07</izz>
                </inertia>
            </inertial>
        </link>

        <!-- Propeller 4-->
        <link name="crazyflie/m4_prop">
            <pose>0.031 0.031 0.021 0 0 0</pose>
            <visual name="crazyflie/m4_visual">
                <geometry>
                <mesh>
                    <uri>model://crazyflie_lcis_description/models/crazyflie/meshes/collada_files/cw_prop.dae</uri>
                </mesh>
                </geometry>
            </visual>

            <inertial>
                <mass>0.0008</mass>
                <inertia>
                <ixx>8.33333E-09</ixx>
                <iyy>1.08333E-07</iyy>
                <izz>1.13333E-07</izz>
                </inertia>
            </inertial>
        </link>


        <joint name="crazyflie/m1_joint" type="revolute">
            <child>crazyflie/m1_prop</child>
            <parent>crazyflie/body</parent>
            <axis>
                <xyz>0 0 1</xyz>
            </axis>
        </joint>
        <joint name="crazyflie/m2_joint" type="revolute">
            <child>crazyflie/m2_prop</child>
            <parent>crazyflie/body</parent>
            <axis>
                <xyz>0 0 1</xyz>
            </axis>
        </joint>
        <joint name="crazyflie/m3_joint" type="revolute">
            <child>crazyflie/m3_prop</child>
            <parent>crazyflie/body</parent>
            <axis>
                <xyz>0 0 1</xyz>
            </axis>
        </joint>
        <joint name="crazyflie/m4_joint" type="revolute">
            <child>crazyflie/m4_prop</child>
            <parent>crazyflie/body</parent>
            <axis>
                <xyz>0 0 1</xyz>
            </axis>
        </joint>


        <plugin
            filename="gz-sim-multicopter-motor-model-system"
            name="gz::sim::systems::MulticopterMotorModel">
            <robotNamespace>crazyflie</robotNamespace>
            <jointName>crazyflie/m1_joint</jointName>
            <linkName>crazyflie/m1_prop</linkName>
            <turningDirection>ccw</turningDirection>
            <timeConstantUp>0.0125</timeConstantUp>
            <timeConstantDown>0.025</timeConstantDown>
            <maxRotVelocity>3052</maxRotVelocity>
            <motorConstant>1.7965e-8</motorConstant>
            <momentConstant>0.005964552</momentConstant>
            <commandSubTopic>command/motor_speed</commandSubTopic>
            <actuator_number>0</actuator_number>
            <rotorDragCoefficient>9.1785e-7</rotorDragCoefficient>
            <rollingMomentCoefficient>0.0000001</rollingMomentCoefficient>
            <motorSpeedPubTopic>motor_speed/0</motorSpeedPubTopic>
            <rotorVelocitySlowdownSim>70</rotorVelocitySlowdownSim>
            <motorType>velocity</motorType>
        </plugin>

        <plugin
            filename="gz-sim-multicopter-motor-model-system"
            name="gz::sim::systems::MulticopterMotorModel">
            <robotNamespace>crazyflie</robotNamespace>
            <jointName>crazyflie/m2_joint</jointName>
            <linkName>crazyflie/m2_prop</linkName>
            <turningDirection>cw</turningDirection>
            <timeConstantUp>0.0125</timeConstantUp>
            <timeConstantDown>0.025</timeConstantDown>
            <maxRotVelocity>3052</maxRotVelocity>
            <motorConstant>1.7965e-8</motorConstant>
            <momentConstant>0.005964552</momentConstant>
            <commandSubTopic>command/motor_speed</commandSubTopic>
            <actuator_number>1</actuator_number>
            <rotorDragCoefficient>9.1785e-7</rotorDragCoefficient>
            <rollingMomentCoefficient>0.0000001</rollingMomentCoefficient>
            <motorSpeedPubTopic>motor_speed/1</motorSpeedPubTopic>
            <rotorVelocitySlowdownSim>70</rotorVelocitySlowdownSim>
            <motorType>velocity</motorType>
        </plugin>

        <plugin
            filename="gz-sim-multicopter-motor-model-system"
            name="gz::sim::systems::MulticopterMotorModel">
            <robotNamespace>crazyflie</robotNamespace>
            <jointName>crazyflie/m3_joint</jointName>
            <linkName>crazyflie/m3_prop</linkName>
            <turningDirection>ccw</turningDirection>
            <timeConstantUp>0.0125</timeConstantUp>
            <timeConstantDown>0.025</timeConstantDown>
            <maxRotVelocity>3052</maxRotVelocity>
            <motorConstant>1.7965e-8</motorConstant>
            <momentConstant>0.005964552</momentConstant>
            <commandSubTopic>command/motor_speed</commandSubTopic>
            <actuator_number>2</actuator_number>
            <rotorDragCoefficient>9.1785e-7</rotorDragCoefficient>
            <rollingMomentCoefficient>0.0000001</rollingMomentCoefficient>
            <motorSpeedPubTopic>motor_speed/2</motorSpeedPubTopic>
            <rotorVelocitySlowdownSim>70</rotorVelocitySlowdownSim>
            <motorType>velocity</motorType>
        </plugin>

        <plugin
            filename="gz-sim-multicopter-motor-model-system"
            name="gz::sim::systems::MulticopterMotorModel">
            <robotNamespace>crazyflie</robotNamespace>
            <jointName>crazyflie/m4_joint</jointName>
            <linkName>crazyflie/m4_prop</linkName>
            <turningDirection>cw</turningDirection>
            <timeConstantUp>0.0125</timeConstantUp>
            <timeConstantDown>0.025</timeConstantDown>
            <maxRotVelocity>3052</maxRotVelocity>
            <motorConstant>1.7965e-8</motorConstant>
            <momentConstant>0.005964552</momentConstant>
            <commandSubTopic>command/motor_speed</commandSubTopic>
            <actuator_number>3</actuator_number>
            <rotorDragCoefficient>9.1785e-7</rotorDragCoefficient>
            <rollingMomentCoefficient>0.0000001</rollingMomentCoefficient>
            <motorSpeedPubTopic>motor_speed/3</motorSpeedPubTopic>
            <rotorVelocitySlowdownSim>70</rotorVelocitySlowdownSim>
            <motorType>velocity</motorType>
        </plugin>

    </model>
</sdf>
